Workbook
Name Slicer_Employee_Name: #N/A
Name Slicer_Employee_Name1: #N/A

Sheet Brokerage 
A1: client_name | B1: policy_number | C1: policy_status | D1: policy_start_date | E1: policy_end_date | F1: product_group | G1: Account Executive | H1: branch_name | I1: solution_group | J1: income_class | K1: Amount | L1: income_due_date | M1: revenue_transaction_type | N1: renewal_status | O1: lapse_reason | P1: last_updated_date
A2: A | B2: 2414 2022 4088 1000 000 | C2: Active | D2: 43209 | E2: 43573 | F2: Marine | G2: Vinay | H2: Ahmedabad | I2: Marine | J2: Renewal | K2: 32186.72 | L2: 43209 | M2: Brokerage | N2: Inception | P2: 43852
A3: Amit | B3: 2.4142028e+18 | C3: Active | D3: 43586 | E3: 43951 | F3: Marine | G3: Abhinav Shivam | H3: Ahmedabad | I3: Marine | J3: New | K3: 23590.71 | L3: 43586 | M3: Brokerage | N3: Inception | P3: 43852
A4: B | B4: 0655001825 01 | C4: Inactive | D4: 43356 | E4: 43720 | F4: Fire | G4: Vinay | H4: Ahmedabad | I4: Construction, Power & Infrastructure | J4: Renewal | K4: 4611.96 | L4: 43356 | M4: Brokerage | N4: Inception | P4: 43852
A5: B | B5: 12139156 | C5: Active | D5: 43721 | E5: 44086 | F5: Fire | G5: Vinay | H5: Ahmedabad | I5: Construction, Power & Infrastructure | J5: Renewal | K5: 4975.41 | L5: 43721 | M5: Brokerage | N5: Renewal | P5: 43852
A6: B | B6: 2200090892 | C6: Active | D6: 43410 | E6: 43774 | F6: Miscellaneous | G6: Vinay | H6: Ahmedabad | I6: Liability | J6: Renewal | K6: 1198.88 | L6: 43410 | M6: Brokerage | N6: Inception | P6: 43852
A7: C | B7: 237164239 00 | C7: Active | D7: 43497 | E7: 43861 | F7: Employee Benefits | G7: Mark | H7: Ahmedabad | I7: Employee Benefits (EB) | J7: Renewal | K7: 1825.43 | L7: 43497 | M7: Brokerage | N7: Inception | P7: 43852
A8: D | B8: 4101190700000015-00 | C8: Active | D8: 43641 | E8: 44006 | F8: Employee Benefits | G8: Abhinav Shivam | H8: Ahmedabad | I8: Employee Benefits (EB) | J8: New | K8: 79833.6 | L8: 43641 | M8: Brokerage | N8: Endorsement | P8: 43852
A9: D | B9: 4101190700000015-00 | C9: Active | D9: 43641 | E9: 44006 | F9: Employee Benefits | G9: Abhinav Shivam | H9: Ahmedabad | I9: Employee Benefits (EB) | J9: New | K9: 11435.86 | L9: 43679 | M9: Brokerage | N9: Endorsement | P9: 43852
A10: E | B10: 2250010276 | C10: Active | D10: 43215 | E10: 43579 | F10: Miscellaneous | G10: Vinay | H10: Ahmedabad | I10: Employee Benefits (EB) | J10: Renewal | K10: 847.38 | L10: 43215 | M10: Brokerage | N10: Inception | P10: 43852
A11: E | B11: 2414 2022 1261 2200 000 | C11: Inactive | D11: 43215 | E11: 43579 | F11: Marine | G11: Vinay | H11: Ahmedabad | I11: Marine | J11: Renewal | K11: 9900 | L11: 43215 | M11: Brokerage | N11: Inception | P11: 43852
A12: E | B12: 2414 2026 2374 7800 000 | C12: Active | D12: 43476 | E12: 43840 | F12: Marine | G12: Vinay | H12: Ahmedabad | I12: Marine | J12: Renewal | K12: 8250 | L12: 43476 | M12: Brokerage | N12: Renewal | P12: 43852
A13: E | B13: 91001900000001 | C13: Active | D13: 43215 | E13: 43579 | F13: Fire | G13: Vinay | H13: Ahmedabad | I13: Property / BI | J13: Renewal | K13: 4093.2 | L13: 43215 | M13: Brokerage | N13: Inception | P13: 43852
A14: F | B14: 2280062933 | C14: Active | D14: 43605 | E14: 43970 | F14: Miscellaneous | G14: Vinay | H14: Ahmedabad | I14: Liability | J14: Renewal | K14: 8117 | L14: 43850 | M14: Brokerage | N14: Renewal | P14: 43852
A15: F | B15: LWC/I2568913/71/05/006144 | C15: Inactive | D15: 43240 | E15: 43604 | F15: Miscellaneous | G15: Vinay | H15: Ahmedabad | I15: Liability | J15: Renewal | K15: 6101.25 | L15: 43240 | M15: Brokerage | N15: Inception | P15: 43852
A16: G | B16: 0865074115 01 | C16: Active | D16: 43263 | E16: 43627 | F16: Marine | G16: Manish Sharma | H16: Ahmedabad | I16: Small Medium Enterpries (SME) | J16: Renewal | K16: 1980 | L16: 43263 | M16: Brokerage | N16: Endorsement | P16: 43852
A17: G | B17: 0865074115 01 | C17: Active | D17: 43263 | E17: 43627 | F17: Marine | G17: Manish Sharma | H17: Ahmedabad | I17: Small Medium Enterpries (SME) | J17: Renewal | K17: 1980 | L17: 43475 | M17: Brokerage | N17: Endorsement | P17: 43852
A18: H | B18: 3.114203e+18 | C18: Active | D18: 43703 | E18: 44068 | F18: Miscellaneous | G18: Animesh Rawat | H18: Ahmedabad | I18: Global Client Network (GNB Inward) | J18: Cross Sell | K18: 2089.25 | L18: 43703 | M18: Brokerage | N18: Inception | P18: 43852
A19: H | B19: OG-19-2202-1018-00000055 | C19: Active | D19: 43466 | E19: 43830 | F19: Marine | G19: Animesh Rawat | H19: Ahmedabad | I19: Global Client Network (GNB Inward) | J19: Cross Sell | K19: 21768.61 | L19: 43466 | M19: Brokerage | N19: Inception | P19: 43852
A20: H | B20: OG-19-2202-3383-00000009 | C20: Active | D20: 43466 | E20: 43830 | F20: Liability | G20: Animesh Rawat | H20: Ahmedabad | I20: Global Client Network (GNB Inward) | J20: Cross Sell | K20: 12019.2 | L20: 43466 | M20: Brokerage | N20: Inception | P20: 43852
A21: I | B21: 640002371 | C21: Active | D21: 43191 | E21: 43555 | F21: Miscellaneous | G21: Animesh Rawat | H21: Ahmedabad | I21: Global Client Network (GNB Inward) | J21: Renewal | K21: 66937.72 | L21: 43191 | M21: Brokerage | N21: Inception | P21: 43852
A22: I | B22: 0830017443 01 | C22: Active | D22: 43231 | E22: 43595 | F22: Marine | G22: Animesh Rawat | H22: Ahmedabad | I22: Global Client Network (GNB Inward) | J22: Renewal | K22: 78374.84 | L22: 43231 | M22: Brokerage | N22: Inception | P22: 43852
A23: I | B23: 180876-0000-00 | C23: Inactive | D23: 43191 | E23: 43555 | F23: Employee Benefits | G23: Mark | H23: Ahmedabad | I23: Employee Benefits (EB) | J23: Renewal | K23: 60000 | L23: 43191 | M23: Brokerage | N23: Inception | P23: 43852
A24: I | B24: 180876-0000-01 | C24: Active | D24: 43556 | E24: 43921 | F24: Employee Benefits | G24: Mark | H24: Ahmedabad | I24: Employee Benefits (EB) | J24: Renewal | K24: 60000 | L24: 43556 | M24: Brokerage | N24: Renewal | P24: 43852
A25: I | B25: 180876-0000-01 | C25: Active | D25: 43556 | E25: 43921 | F25: Employee Benefits | G25: Mark | H25: Ahmedabad | I25: Employee Benefits (EB) | J25: Renewal | K25: 60000 | L25: 43556 | M25: Brokerage | N25: Renewal | P25: 43852
A26: I | B26: 2250002346 | C26: Active | D26: 43191 | E26: 43555 | F26: Miscellaneous | G26: Animesh Rawat | H26: Ahmedabad | I26: Global Client Network (GNB Inward) | J26: Renewal | K26: 4715.63 | L26: 43191 | M26: Brokerage | N26: Inception | P26: 43852
A27: I | B27: 3.1242014e+18 | C27: Active | D27: 43191 | E27: 43555 | F27: Liability | G27: Animesh Rawat | H27: Ahmedabad | I27: Global Client Network (GNB Inward) | J27: Renewal | K27: 22755.25 | L27: 43191 | M27: Brokerage | N27: Inception | P27: 43852
A28: I | B28: P0119200001/9999/100017 | C28: Active | D28: 43191 | E28: 43555 | F28: Liability | G28: Shivani Sharma | H28: Ahmedabad | I28: Global Client Network (GNB Inward) | J28: Renewal | K28: 26443.63 | L28: 43191 | M28: Brokerage | N28: Inception | P28: 43852
A29: J | B29: 0865078325 00 | C29: Inactive | D29: 43196 | E29: 43560 | F29: Marine | G29: Vinay | H29: Ahmedabad | I29: Marine | J29: Renewal | K29: 49499.84 | L29: 43196 | M29: Brokerage | N29: Endorsement | P29: 43852
A30: J | B30: 0865078325 00 | C30: Inactive | D30: 43196 | E30: 43560 | F30: Marine | G30: Vinay | H30: Ahmedabad | I30: Marine | J30: Renewal | L30: 43384 | M30: Brokerage | N30: Endorsement | P30: 43852
A31: J | B31: 0865078325 00 | C31: Inactive | D31: 43196 | E31: 43560 | F31: Marine | G31: Vinay | H31: Ahmedabad | I31: Marine | J31: Renewal | K31: 16500 | L31: 43482 | M31: Brokerage | N31: Endorsement | P31: 43852
A32: J | B32: '0865078325 01 | C32: Active | D32: 43561 | E32: 43926 | F32: Marine | G32: Vinay | H32: Ahmedabad | I32: Marine | J32: Renewal | K32: 26400 | L32: 43561 | M32: Brokerage | N32: Renewal | P32: 43852
A33: J | B33: 0865080591 00 | C33: Active | D33: 43332 | E33: 43696 | F33: Marine | G33: Vinay | H33: Ahmedabad | I33: Marine | J33: Renewal | K33: 3300 | L33: 43332 | M33: Brokerage | N33: Inception | P33: 43852
A34: J | B34: 0865081032 00 | C34: Active | D34: 43354 | E34: 43718 | F34: Marine | G34: Vinay | H34: Ahmedabad | I34: Marine | J34: Renewal | K34: 1072.5 | L34: 43354 | M34: Brokerage | N34: Inception | P34: 43852
A35: J | B35: '310304111710000871 | C35: Active | D35: 43186 | E35: 43550 | F35: Fire | G35: Vinay | H35: Ahmedabad | I35: Property / BI | J35: Renewal | K35: 4002.46 | L35: 43186 | M35: Brokerage | N35: Inception | P35: 43852
A36: J | B36: 3.1030411e+17 | C36: Active | D36: 43326 | E36: 43690 | F36: Fire | G36: Vinay | H36: Ahmedabad | I36: Property / BI | J36: Renewal | K36: 1374.25 | L36: 43326 | M36: Brokerage | N36: Inception | P36: 43852
A37: J | B37: 3.1030459e+18 | C37: Active | D37: 43186 | E37: 43550 | F37: Fire | G37: Vinay | H37: Ahmedabad | I37: Property / BI | J37: Cross Sell | K37: 566.25 | L37: 43186 | M37: Brokerage | N37: Inception | P37: 43852
A38: J | B38: '310304591810000063 | C38: Active | D38: 43326 | E38: 43690 | F38: Miscellaneous | G38: Vinay | H38: Ahmedabad | I38: Property / BI | J38: Renewal | K38: 445 | L38: 43326 | M38: Brokerage | N38: Inception | P38: 43852
A39: K | B39: '310300111910000401 | C39: Active | D39: 43709 | E39: 44074 | F39: Fire | G39: Vinay | H39: Ahmedabad | I39: Property / BI | J39: Renewal | K39: 13114.95 | L39: 43709 | M39: Brokerage | N39: Renewal | P39: 43852
A40: K | B40: 3.1030411e+17 | C40: Inactive | D40: 43344 | E40: 43708 | F40: Fire | G40: Vinay | H40: Ahmedabad | I40: Property / BI | J40: Renewal | K40: 2049.42 | L40: 43344 | M40: Brokerage | N40: Inception | P40: 43852
...

Sheet fees
A1: client_name | B1: branch_name | C1: solution_group | D1: Account Executive | E1: income_class | F1: Amount | G1: income_due_date | H1: revenue_transaction_type
A2: A | B2: Ahmedabad | C2: Construction, Power & Infrastructure | D2: Nishant Sharma | E2: Cross Sell | F2: 139240 | G2: 43663 | H2: Fees
A3: A | B3: Ahmedabad | C3: Construction, Power & Infrastructure | D3: Nishant Sharma | E3: Cross Sell | F3: 139240 | G3: 43486 | H3: Fees
A4: B | B4: Ahmedabad | C4: GL Client Network (GNB Inward) | D4: Divya Dhingra | E4: Renewal | F4: 2200 | G4: 43819 | H4: Fees
A5: C | B5: Ahmedabad | C5: GL Client Network (GNB Inward) | D5: Divya Dhingra | E5: Renewal | F5: 4500 | G5: 43490 | H5: Fees
A6: D | B6: Ahmedabad | C6: Construction, Power & Infrastructure | D6: Nishant Sharma | E6: Cross Sell | F6: 118000 | G6: 43539 | H6: Fees
A7: E | B7: Ahmedabad | C7: GL Client Network (GNB Inward) | D7: Divya Dhingra | E7: Renewal | F7: 2800 | G7: 43613 | H7: Fees
A8: F | B8: Ahmedabad | C8: GL Client Network (GNB Inward) | D8: Divya Dhingra | E8: Renewal | F8: 3241 | G8: 43490 | H8: Fees
A9: G | B9: Ahmedabad | C9: Liability | D9: Neel Jain | E9: New | F9: 100000 | G9: 43565 | H9: Fees
A10: H | B10: Ahmedabad | C10: GL Client Network (GNB Inward) | D10: Divya Dhingra | E10: Renewal | F10: 5310 | G10: 43805 | H10: Fees

Sheet Individual bdgt 
A1: Branch | B1: Employee Name | C1: New Role2 | D1: New Budget | E1: Cross sell bugdet | F1: Renewal Budget
A2: Ahmedabad | B2: Anil Tailor | C2: Hunter & Farmer | D2: 0 | E2: 250000 | F2: 1500000
A3: Ahmedabad | B3: Ankita Shah | C3: Servicer
A4: Ahmedabad | B4: Divya Dhingra | C4: Servicer | D4: 0 | E4: 0 | F4: 0
A5: Ahmedabad | B5: Neel Jain | C5: BH | D5: 1000000 | E5: 500000 | F5: 1010000
A6: Ahmedabad | B6: Nishant Sharma | C6: Hunter & Farmer | D6: 1250000 | E6: 3500000 | F6: 750000
A7: Ahmedabad | B7: Ritesh Sharma | C7: Servicer Claims
A8: Ahmedabad | B8: Shloka Shelat | C8: Hunter & Farmer | D8: 500000 | E8: 1250000 | F8: 500000
A9: Ahmedabad | B9: Shobhit Agarwal | C9: Hunter & Farmer | D9: 1350000 | E9: 750000 | F9: 750000
A10: Ahmedabad | B10: Vaibhav K Thaker | C10: Servicer | D10: 0 | E10: 0 | F10: 0
A11: Ahmedabad | B11: Vidit Shah | C11: Farmer & Servicer | D11: 0 | E11: 1040000 | F11: 5010000

Sheet Invoice
A1: invoice_number | B1: invoice_date | C1: revenue_transaction_type | D1: branch_name | E1: solution_group | F1: Account Executive | G1: income_class | H1: client_name | I1: policy_number | J1: Amount | K1: income_due_date
A2: 1900001087 | B2: 43566 | C2: Fees | D2: Ahmedabad | E2: Liability | F2: Neel Jain | G2: New | H2: I | J2: 84746 | K2: 43565
A3: 1900001106 | B3: 43602 | C3: Brokerage | D3: Ahmedabad | E3: Global Client Network (GNB Inward) | F3: Divya Dhingra | G3: Renewal | H3: M | I3: 2.4142021e+18 | J3: 86724 | K3: 43466
A4: 1900001110 | B4: 43602 | C4: Brokerage | D4: Ahmedabad | E4: Global Client Network (GNB Inward) | F4: Divya Dhingra | G4: Renewal | H4: S | I4: OG-19-2202-1018-00000060 | J4: 148500 | K4: 43525
A5: 1900001136 | B5: 43615 | C5: Brokerage | D5: Ahmedabad | E5: Global Client Network (GNB Inward) | F5: Divya Dhingra | G5: Cross Sell | H5: V | I5: OG-19-2202-3383-00000010 | J5: 12019 | K5: 43466
A6: 1900001164 | B6: 43627 | C6: Brokerage | D6: Ahmedabad | E6: Global Client Network (GNB Inward) | F6: Divya Dhingra | G6: Renewal | H6: I | I6: 020P000098803000 | J6: 12500 | K6: 43522
A7: 1900001165 | B7: 43627 | C7: Brokerage | D7: Ahmedabad | E7: Employee Benefits (EB) | F7: Shloka Shelat | G7: New | H7: I | I7: 206314000000 | J7: 58300 | K7: 43512
A8: 1900001167 | B8: 43629 | C8: Brokerage | D8: Ahmedabad | E8: Global Client Network (GNB Inward) | F8: Divya Dhingra | G8: Cross Sell | H8: A | I8: OG-19-2202-3383-00000009 | J8: 12019 | K8: 43466
A9: 1900001168 | B9: 43629 | C9: Brokerage | D9: Ahmedabad | E9: Global Client Network (GNB Inward) | F9: Divya Dhingra | G9: Cross Sell | H9: C | I9: OG-19-2202-3383-00000008 | J9: 30048 | K9: 43466
A10: 1900001169 | B10: 43629 | C10: Brokerage | D10: Ahmedabad | E10: Global Client Network (GNB Inward) | F10: Divya Dhingra | G10: Renewal | H10: P | I10: 3.1242016e+18 | J10: 14394 | K10: 43467
A11: 1900001282 | B11: 43659 | C11: Brokerage | D11: Ahmedabad | E11: Employee Benefits (EB) | F11: Ankita Shah | H11: S | I11: H0048996 | J11: 32392 | K11: 43595
A12: 1900001293 | B12: 43662 | C12: Brokerage | D12: Ahmedabad | E12: Liability | F12: Vidit Shah | G12: Cross Sell | H12: M | I12: '001P000202300000 | J12: 162500 | K12: 43560
A13: 1900001294 | B13: 43662 | C13: Brokerage | D13: Ahmedabad | E13: Liability | F13: Vidit Shah | G13: Cross Sell | H13: M | I13: '001P000203500000 | J13: 250000 | K13: 43573
A14: 1900001304 | B14: 43663 | C14: Brokerage | D14: Ahmedabad | E14: Global Client Network (GNB Inward) | F14: Divya Dhingra | G14: Cross Sell | H14: I | I14: 2280082714 | J14: 2646 | K14: 43535
A15: 1900001305 | B15: 43663 | C15: Brokerage | D15: Ahmedabad | E15: Global Client Network (GNB Inward) | F15: Divya Dhingra | H15: F | I15: 8502066 | J15: 18150 | K15: 43468
A16: 1900001306 | B16: 43663 | C16: Brokerage | D16: Ahmedabad | E16: Liability | F16: Nishant Sharma | G16: Cross Sell | H16: L | I16: 2999202758217600000" | J16: 60025 | K16: 43577
A17: 1900001308 | B17: 43663 | C17: Brokerage | D17: Ahmedabad | E17: Construction, Power & Infrastructure | F17: Shloka Shelat | G17: Cross Sell | H17: G | I17: 9.9000044e+19 | J17: 134736 | K17: 43580
A18: 1900001342 | B18: 43669 | C18: Brokerage | D18: Ahmedabad | E18: Employee Benefits (EB) | F18: Ankita Shah | G18: Renewal | H18: S | I18: H0048996 | J18: 914999 | K18: 43466
A19: 1900001354 | B19: 43670 | C19: Brokerage | D19: Ahmedabad | E19: Global Client Network (GNB Inward) | F19: Divya Dhingra | G19: Cross Sell | H19: P | I19: 3.1142027e+18 | J19: 2942 | K19: 43566
A20: 1900001355 | B20: 43670 | C20: Brokerage | D20: Ahmedabad | E20: Global Client Network (GNB Inward) | F20: Divya Dhingra | G20: Cross Sell | H20: M | I20: OG-19-2202-1002-00001981 | J20: 6740 | K20: 43528
A21: 1900001356 | B21: 43670 | C21: Brokerage | D21: Ahmedabad | E21: Global Client Network (GNB Inward) | F21: Divya Dhingra | G21: Renewal | H21: M | I21: OG-19-2202-1002-00001901 | J21: 6740 | K21: 43513
A22: 1900001361 | B22: 43673 | C22: Brokerage | D22: Ahmedabad | E22: Liability | F22: Shloka Shelat | G22: Cross Sell | H22: T | I22: 41045707 | J22: 74250 | K22: 43556
A23: 1900001376 | B23: 43675 | C23: Brokerage | D23: Ahmedabad | E23: Employee Benefits (EB) | F23: Ankita Shah | H23: S | I23: H0056637 | J23: 1614 | K23: 43535
A24: 1900001377 | B24: 43675 | C24: Brokerage | D24: Ahmedabad | E24: Marine | F24: Vidit Shah | G24: Cross Sell | H24: P | I24: '99000021180100000013 | J24: 11540 | K24: 43494
A25: 1900001385 | B25: 43677 | C25: Brokerage | D25: Ahmedabad | E25: Global Client Network (GNB Inward) | F25: Divya Dhingra | H25: S | I25: P0019200001/9999/100301 | J25: 2140 | K25: 43495
A26: 1900001388 | B26: 43677 | C26: Brokerage | D26: Ahmedabad | E26: Global Client Network (GNB Inward) | F26: Divya Dhingra | G26: Renewal | H26: F | I26: 0000000008502066-01 | J26: 45375 | K26: 43525
A27: 1900001390 | B27: 43677 | C27: Brokerage | D27: Ahmedabad | E27: Global Client Network (GNB Inward) | F27: Divya Dhingra | G27: Cross Sell | H27: M | I27: 32119154 | J27: 11593 | K27: 43556
A28: 1900001392 | B28: 43677 | C28: Brokerage | D28: Ahmedabad | E28: Employee Benefits (EB) | F28: Ankita Shah | H28: S | I28: H0048996 | J28: 46995 | K28: 43494
A29: 1900001393 | B29: 43677 | C29: Brokerage | D29: Ahmedabad | E29: Global Client Network (GNB Inward) | F29: Divya Dhingra | G29: Cross Sell | H29: M | I29: OG-19-2202-4010-00002245 | J29: 529 | K29: 43514
A30: 1900001394 | B30: 43677 | C30: Brokerage | D30: Ahmedabad | E30: Global Client Network (GNB Inward) | F30: Divya Dhingra | G30: Renewal | H30: B | I30: OG-19-2202-1018-00000059 | J30: 18563 | K30: 43525
A31: 1900001396 | B31: 43677 | C31: Brokerage | D31: Ahmedabad | E31: Employee Benefits (EB) | F31: Ankita Shah | H31: S | I31: H0048996 | J31: 27435 | K31: 43488
A32: 1900001397 | B32: 43677 | C32: Brokerage | D32: Ahmedabad | E32: Employee Benefits (EB) | F32: Ankita Shah | G32: Renewal | H32: W | I32: 505373-01 | J32: 25336 | K32: 43522
A33: 1900001398 | B33: 43677 | C33: Brokerage | D33: Ahmedabad | E33: Employee Benefits (EB) | F33: Ankita Shah | H33: W | I33: H0067187 | J33: 10772 | K33: 43538
A34: 1900001403 | B34: 43677 | C34: Brokerage | D34: Ahmedabad | E34: Employee Benefits (EB) | F34: Ankita Shah | H34: W | I34: H0067187 | J34: 9283 | K34: 43573
A35: 1900001404 | B35: 43677 | C35: Brokerage | D35: Ahmedabad | E35: Employee Benefits (EB) | F35: Ankita Shah | H35: W | I35: H0067187 | J35: 6903 | K35: 43615
A36: 1900001405 | B36: 43677 | C36: Brokerage | D36: Ahmedabad | E36: Construction, Power & Infrastructure | F36: Vidit Shah | G36: Renewal | H36: P | I36: '99000044190700000001 | J36: 90663 | K36: 43556
A37: 1900001583 | B37: 43691 | C37: Brokerage | D37: Ahmedabad | E37: Employee Benefits (EB) | F37: Ankita Shah | G37: Renewal | H37: T | I37: 100200080123/01/00 | J37: 156000 | K37: 43469
A38: 1900001602 | B38: 43694 | C38: Brokerage | D38: Ahmedabad | E38: Global Client Network (GNB Inward) | F38: Divya Dhingra | G38: Cross Sell | H38: V | I38: OG-19-2202-1018-00000054 | J38: 21157 | K38: 43466
A39: 1900001603 | B39: 43694 | C39: Brokerage | D39: Ahmedabad | E39: Global Client Network (GNB Inward) | F39: Divya Dhingra | G39: Cross Sell | H39: C | I39: OG-19-2202-1018-00000053 | J39: 77787 | K39: 43466
A40: 1900001604 | B40: 43694 | C40: Brokerage | D40: Ahmedabad | E40: Global Client Network (GNB Inward) | F40: Divya Dhingra | G40: Cross Sell | H40: M | I40: OG-19-2202-4001-00011127 | J40: 8468 | K40: 43514
...

Sheet Opportunity
A1: opportunity_name | B1: opportunity_id | C1: Account Executive | D1: premium_amount | E1: revenue_amount | F1: closing_date | G1: stage | H1: branch | I1: specialty | J1: product_group | K1: product_sub_group | L1: risk_details
A2: EL-Group Mediclaim | B2: OPP1900001042 | C2: Animesh Rawat | D2: 8000000 | E2: 400000 | F2: 43782 | G2: Qualify Opportunity | H2: Ahmedabad | I2: Employee Benefits (EB) | J2: Employee Benefits | K2: Mediclaim | L2: Group Medical
A3: AL GPA | B3: OPP1900001047 | C3: Shivani Sharma | D3: 200000 | E3: 30000 | F3: 43921 | G3: Qualify Opportunity | H3: Ahmedabad | I3: Employee Benefits (EB) | J3: Employee Benefits | K3: Mediclaim | L3: Group Personal Accident
A4: BL - Marine STOP | B4: OPP1900001048 | C4: Shivani Sharma | D4: 0 | E4: 100000 | F4: 44012 | G4: Qualify Opportunity | H4: Ahmedabad | I4: Marine | J4: Marine | K4: Marine Hull | L4: Charterers' Liability Policy
A5: II-Marine | B5: OPP1900001050 | C5: Shivani Sharma | D5: 0 | E5: 100000 | F5: 43921 | G5: Qualify Opportunity | H5: Ahmedabad | I5: Marine | J5: Marine | K5: Marine Hull | L5: Charterers' Liability Policy
A6: PIL-Credit Insurance | B6: OPP1900001051 | C6: Shivani Sharma | D6: 1200000 | E6: 100000 | F6: 43921 | G6: Qualify Opportunity | H6: Ahmedabad | I6: Trade Credit &amp; Political Risk | J6: Miscellaneous | K6: Miscellaneous | L6: Trade Credit Insurance
A7: PIL-CGL | B7: OPP1900001052 | C7: Shivani Sharma | D7: 0 | E7: 100000 | F7: 43982 | G7: Qualify Opportunity | H7: Ahmedabad | I7: Liability | J7: Liability | K7: Financial Lines | L7: Commercial General Liability
A8: PIL -Marine | B8: OPP1900001053 | C8: Shivani Sharma | D8: 0 | E8: 100000 | F8: 43982 | G8: Qualify Opportunity | H8: Ahmedabad | I8: Marine | J8: Marine | K8: Marine Hull | L8: Charterers' Liability Policy
A9: SGL- GMC | B9: OPP1900001054 | C9: Shivani Sharma | D9: 0 | E9: 125000 | F9: 44012 | G9: Qualify Opportunity | H9: Ahmedabad | I9: Employee Benefits (EB) | J9: Employee Benefits | K9: Mediclaim | L9: Group Medical
A10: Sandesh - Marine | B10: OPP1900001055 | C10: Shivani Sharma | D10: 0 | E10: 100000 | F10: 43921 | G10: Qualify Opportunity | H10: Ahmedabad | I10: Marine | J10: Marine | K10: Marine Hull | L10: Charterers' Liability Policy
A11: VS.-Marine | B11: OPP1900001056 | C11: Shivani Sharma | D11: 0 | E11: 200000 | F11: 43921 | G11: Qualify Opportunity | H11: Ahmedabad | I11: Marine | J11: Marine | K11: Marine Hull | L11: Charterers' Liability Policy
A12: II - GMC | B12: OPP1900001057 | C12: Shivani Sharma | D12: 0 | E12: 75000 | F12: 43921 | G12: Qualify Opportunity | H12: Ahmedabad | I12: Employee Benefits (EB) | J12: Employee Benefits | K12: Mediclaim | L12: Group Medical
A13: II - GPA | B13: OPP1900001058 | C13: Shivani Sharma | D13: 0 | E13: 25000 | F13: 43921 | G13: Qualify Opportunity | H13: Ahmedabad | I13: Employee Benefits (EB) | J13: Employee Benefits | K13: Mediclaim | L13: Group Personal Accident
... A50: VS.-D & O | B50: OPP1900002104 | C50: Shivani Sharma | D50: 0 | E50: 50000 | F50: 43921 | G50: Qualify Opportunity | H50: Ahmedabad | I50: Liability | J50: Liability | K50: Financial Lines | L50: Director &amp; Officers / Management Liability

Sheet Meeting
A1: Account Executive | B1: branch_name | C1: meeting_date
A2: Abhinav Shivam | B2: Ahmedabad | C2: 43755
A3: Abhinav Shivam | B3: Ahmedabad | C3: 43755
A4: Abhinav Shivam | B4: Ahmedabad | C4: 43823
A5: Abhinav Shivam | B5: Ahmedabad | C5: 43833
A6: Abhinav Shivam | B6: Ahmedabad | C6: 43838
A7: Abhinav Shivam | B7: Ahmedabad | C7: 43838
A8: Abhinav Shivam | B8: Ahmedabad | C8: 43839
A9: Vinay | B9: Ahmedabad | C9: 43832
A10: Vinay | B10: Ahmedabad | C10: 43833
A11: Vinay | B11: Ahmedabad | C11: 43836
A12: Vinay | B12: Ahmedabad | C12: 43837
A13: Vinay | B13: Ahmedabad | C13: 43838
... A35: Mark | B35: Ahmedabad | C35: 43843

Sheet Multiple files
B2: Invoice | E2: Target Budget
B3: Row Labels | C3: Sum of Amount | E3: Sum of New Budget | F3: Sum of Cross sell bugdet | G3: Sum of Renewal Budget
B4: Cross Sell | C4: 3040813 | E4: 19673793 | F4: 20083111 | G4: 12319455
B5: New | C5: 827822
B6: Renewal | C6: 8394071
B7: Grand Total | C7: 12262706
E8: Achievement | G8: placed Ach% | H8: Invoice Ach%
B9: Brokerage | E9: Cross Sell | F9: =GETPIVOTDATA("[Measures].[Sum of Amount 2]",$B$10,"[Brokerage].[Income Class]","[Brokerage].[Income Class].&[Cross Sell]")+GETPIVOTDATA("[Measures].[Sum of Amount 3]",$B$18,"[Fees].[Income Class]","[Fees].[Income Class].&[Cross Sell]") -> #REF! | G9: =F9/GETPIVOTDATA("[Measures].[Sum of Cross sell bugdet]",$E$3) -> #REF! | H9: =GETPIVOTDATA("[Measures].[Sum of Amount]",$B$3,"[Invoice].[Imcome Class]","[Invoice].[Imcome Class].&[Cross Sell]")/GETPIVOTDATA("[Measures].[Sum of Cross sell bugdet]",$E$3) -> #REF!
B10: Row Labels | C10: Sum of Amount | E10: New | F10: =GETPIVOTDATA("[Measures].[Sum of Amount 2]",$B$10,"[Brokerage].[Income Class]","[Brokerage].[Income Class].&[New]")+GETPIVOTDATA("[Measures].[Sum of Amount 3]",$B$18,"[Fees].[Income Class]","[Fees].[Income Class].&[New]") -> #REF! | G10: =F10/GETPIVOTDATA("[Measures].[Sum of New Budget]",$E$3) -> #REF! | H10: =GETPIVOTDATA("[Measures].[Sum of Amount]",$B$3,"[Invoice].[Imcome Class]","[Invoice].[Imcome Class].&[New]")/GETPIVOTDATA("[Measures].[Sum of New Budget]",$E$3) -> #REF!
B11: (blank) | C11: 1558.76 | E11: Renewal | F11: =GETPIVOTDATA("[Measures].[Sum of Amount 2]",$B$10,"[Brokerage].[Income Class]","[Brokerage].[Income Class].&[Renewal]")+GETPIVOTDATA("[Measures].[Sum of Amount 3]",$B$18,"[Fees].[Income Class]","[Fees].[Income Class].&[Renewal]") -> #REF! | G11: =F11/GETPIVOTDATA("[Measures].[Sum of Renewal Budget]",$E$3) -> #REF! | H11: =GETPIVOTDATA("[Measures].[Sum of Amount]",$B$3,"[Invoice].[Imcome Class]","[Invoice].[Imcome Class].&[Renewal]")/GETPIVOTDATA("[Measures].[Sum of Renewal Budget]",$E$3) -> #REF!
B12: Cross Sell | C12: 12644773
B13: New | C13: 3431629.3
B14: Renewal | C14: 18489220
B15: Grand Total | C15: 34567181
B17: Fees
B18: Row Labels | C18: Sum of Amount
B19: Cross Sell | C19: 396480
B20: New | C20: 100000
B21: Renewal | C21: 18051
B22: Grand Total | C22: 514531

Sheet Placed achivement
A1: client_name | B1: policy_number | C1: policy_status | D1: policy_start_date | E1: policy_end_date | F1: product_group | G1: Account Executive | H1: branch_name | I1: solution_group | J1: income_class | K1: Amount | L1: income_due_date | M1: revenue_transaction_type | N1: renewal_status | O1: last_updated_date
A2: A | B2: 2414 2022 4088 1000 000 | C2: Active | D2: 43209 | E2: 43573 | F2: Marine | G2: Vinay | H2: Ahmedabad | I2: Marine | J2: Renewal | K2: 32186.72 | L2: 43209 | M2: Brokerage | N2: Inception | O2: 43852
A3: Amit | B3: 2.4142028e+18 | C3: Active | D3: 43586 | E3: 43951 | F3: Marine | G3: Abhinav Shivam | H3: Ahmedabad | I3: Marine | J3: New | K3: 23590.71 | L3: 43586 | M3: Brokerage | N3: Inception | O3: 43852
A4: B | B4: 0655001825 01 | C4: Inactive | D4: 43356 | E4: 43720 | F4: Fire | G4: Vinay | H4: Ahmedabad | I4: Construction, Power & Infrastructure | J4: Renewal | K4: 4611.96 | L4: 43356 | M4: Brokerage | N4: Inception | O4: 43852
A5: B | B5: 12139156 | C5: Active | D5: 43721 | E5: 44086 | F5: Fire | G5: Vinay | H5: Ahmedabad | I5: Construction, Power & Infrastructure | J5: Renewal | K5: 4975.41 | L5: 43721 | M5: Brokerage | N5: Renewal | O5: 43852
A6: B | B6: 2200090892 | C6: Active | D6: 43410 | E6: 43774 | F6: Miscellaneous | G6: Vinay | H6: Ahmedabad | I6: Liability | J6: Renewal | K6: 1198.88 | L6: 43410 | M6: Brokerage | N6: Inception | O6: 43852
A7: C | B7: 237164239 00 | C7: Active | D7: 43497 | E7: 43861 | F7: Employee Benefits | G7: Mark | H7: Ahmedabad | I7: Employee Benefits (EB) | J7: Renewal | K7: 1825.43 | L7: 43497 | M7: Brokerage | N7: Inception | O7: 43852
A8: D | B8: 4101190700000015-00 | C8: Active | D8: 43641 | E8: 44006 | F8: Employee Benefits | G8: Abhinav Shivam | H8: Ahmedabad | I8: Employee Benefits (EB) | J8: New | K8: 79833.6 | L8: 43641 | M8: Brokerage | N8: Endorsement | O8: 43852
A9: D | B9: 4101190700000015-00 | C9: Active | D9: 43641 | E9: 44006 | F9: Employee Benefits | G9: Abhinav Shivam | H9: Ahmedabad | I9: Employee Benefits (EB) | J9: New | K9: 11435.86 | L9: 43679 | M9: Brokerage | N9: Endorsement | O9: 43852
A10: E | B10: 2250010276 | C10: Active | D10: 43215 | E10: 43579 | F10: Miscellaneous | G10: Vinay | H10: Ahmedabad | I10: Employee Benefits (EB) | J10: Renewal | K10: 847.38 | L10: 43215 | M10: Brokerage | N10: Inception | O10: 43852
A11: E | B11: 2414 2022 1261 2200 000 | C11: Inactive | D11: 43215 | E11: 43579 | F11: Marine | G11: Vinay | H11: Ahmedabad | I11: Marine | J11: Renewal | K11: 9900 | L11: 43215 | M11: Brokerage | N11: Inception | O11: 43852
A12: E | B12: 2414 2026 2374 7800 000 | C12: Active | D12: 43476 | E12: 43840 | F12: Marine | G12: Vinay | H12: Ahmedabad | I12: Marine | J12: Renewal | K12: 8250 | L12: 43476 | M12: Brokerage | N12: Renewal | O12: 43852
A13: E | B13: 91001900000001 | C13: Active | D13: 43215 | E13: 43579 | F13: Fire | G13: Vinay | H13: Ahmedabad | I13: Property / BI | J13: Renewal | K13: 4093.2 | L13: 43215 | M13: Brokerage | N13: Inception | O13: 43852
A14: F | B14: 2280062933 | C14: Active | D14: 43605 | E14: 43970 | F14: Miscellaneous | G14: Vinay | H14: Ahmedabad | I14: Liability | J14: Renewal | K14: 8117 | L14: 43850 | M14: Brokerage | N14: Renewal | O14: 43852
A15: F | B15: LWC/I2568913/71/05/006144 | C15: Inactive | D15: 43240 | E15: 43604 | F15: Miscellaneous | G15: Vinay | H15: Ahmedabad | I15: Liability | J15: Renewal | K15: 6101.25 | L15: 43240 | M15: Brokerage | N15: Inception | O15: 43852
A16: G | B16: 0865074115 01 | C16: Active | D16: 43263 | E16: 43627 | F16: Marine | G16: Manish Sharma | H16: Ahmedabad | I16: Small Medium Enterpries (SME) | J16: Renewal | K16: 1980 | L16: 43263 | M16: Brokerage | N16: Endorsement | O16: 43852
A17: G | B17: 0865074115 01 | C17: Active | D17: 43263 | E17: 43627 | F17: Marine | G17: Manish Sharma | H17: Ahmedabad | I17: Small Medium Enterpries (SME) | J17: Renewal | K17: 1980 | L17: 43475 | M17: Brokerage | N17: Endorsement | O17: 43852
A18: H | B18: 3.114203e+18 | C18: Active | D18: 43703 | E18: 44068 | F18: Miscellaneous | G18: Animesh Rawat | H18: Ahmedabad | I18: Global Client Network (GNB Inward) | J18: Cross Sell | K18: 2089.25 | L18: 43703 | M18: Brokerage | N18: Inception | O18: 43852
A19: H | B19: OG-19-2202-1018-00000055 | C19: Active | D19: 43466 | E19: 43830 | F19: Marine | G19: Animesh Rawat | H19: Ahmedabad | I19: Global Client Network (GNB Inward) | J19: Cross Sell | K19: 21768.61 | L19: 43466 | M19: Brokerage | N19: Inception | O19: 43852
A20: H | B20: OG-19-2202-3383-00000009 | C20: Active | D20: 43466 | E20: 43830 | F20: Liability | G20: Animesh Rawat | H20: Ahmedabad | I20: Global Client Network (GNB Inward) | J20: Cross Sell | K20: 12019.2 | L20: 43466 | M20: Brokerage | N20: Inception | O20: 43852
A21: I | B21: 640002371 | C21: Active | D21: 43191 | E21: 43555 | F21: Miscellaneous | G21: Animesh Rawat | H21: Ahmedabad | I21: Global Client Network (GNB Inward) | J21: Renewal | K21: 66937.72 | L21: 43191 | M21: Brokerage | N21: Inception | O21: 43852
A22: I | B22: 0830017443 01 | C22: Active | D22: 43231 | E22: 43595 | F22: Marine | G22: Animesh Rawat | H22: Ahmedabad | I22: Global Client Network (GNB Inward) | J22: Renewal | K22: 78374.84 | L22: 43231 | M22: Brokerage | N22: Inception | O22: 43852
A23: I | B23: 180876-0000-00 | C23: Inactive | D23: 43191 | E23: 43555 | F23: Employee Benefits | G23: Mark | H23: Ahmedabad | I23: Employee Benefits (EB) | J23: Renewal | K23: 60000 | L23: 43191 | M23: Brokerage | N23: Inception | O23: 43852
A24: I | B24: 180876-0000-01 | C24: Active | D24: 43556 | E24: 43921 | F24: Employee Benefits | G24: Mark | H24: Ahmedabad | I24: Employee Benefits (EB) | J24: Renewal | K24: 60000 | L24: 43556 | M24: Brokerage | N24: Renewal | O24: 43852
A25: I | B25: 180876-0000-01 | C25: Active | D25: 43556 | E25: 43921 | F25: Employee Benefits | G25: Mark | H25: Ahmedabad | I25: Employee Benefits (EB) | J25: Renewal | K25: 60000 | L25: 43556 | M25: Brokerage | N25: Renewal | O25: 43852
A26: I | B26: 2250002346 | C26: Active | D26: 43191 | E26: 43555 | F26: Miscellaneous | G26: Animesh Rawat | H26: Ahmedabad | I26: Global Client Network (GNB Inward) | J26: Renewal | K26: 4715.63 | L26: 43191 | M26: Brokerage | N26: Inception | O26: 43852
A27: I | B27: 3.1242014e+18 | C27: Active | D27: 43191 | E27: 43555 | F27: Liability | G27: Animesh Rawat | H27: Ahmedabad | I27: Global Client Network (GNB Inward) | J27: Renewal | K27: 22755.25 | L27: 43191 | M27: Brokerage | N27: Inception | O27: 43852
A28: I | B28: P0119200001/9999/100017 | C28: Active | D28: 43191 | E28: 43555 | F28: Liability | G28: Shivani Sharma | H28: Ahmedabad | I28: Global Client Network (GNB Inward) | J28: Renewal | K28: 26443.63 | L28: 43191 | M28: Brokerage | N28: Inception | O28: 43852
A29: J | B29: 0865078325 00 | C29: Inactive | D29: 43196 | E29: 43560 | F29: Marine | G29: Vinay | H29: Ahmedabad | I29: Marine | J29: Renewal | K29: 49499.84 | L29: 43196 | M29: Brokerage | N29: Endorsement | O29: 43852
A30: J | B30: 0865078325 00 | C30: Inactive | D30: 43196 | E30: 43560 | F30: Marine | G30: Vinay | H30: Ahmedabad | I30: Marine | J30: Renewal | L30: 43384 | M30: Brokerage | N30: Endorsement | O30: 43852
A31: J | B31: 0865078325 00 | C31: Inactive | D31: 43196 | E31: 43560 | F31: Marine | G31: Vinay | H31: Ahmedabad | I31: Marine | J31: Renewal | K31: 16500 | L31: 43482 | M31: Brokerage | N31: Endorsement | O31: 43852
A32: J | B32: '0865078325 01 | C32: Active | D32: 43561 | E32: 43926 | F32: Marine | G32: Vinay | H32: Ahmedabad | I32: Marine | J32: Renewal | K32: 26400 | L32: 43561 | M32: Brokerage | N32: Renewal | O32: 43852
A33: J | B33: 0865080591 00 | C33: Active | D33: 43332 | E33: 43696 | F33: Marine | G33: Vinay | H33: Ahmedabad | I33: Marine | J33: Renewal | K33: 3300 | L33: 43332 | M33: Brokerage | N33: Inception | O33: 43852
A34: J | B34: 0865081032 00 | C34: Active | D34: 43354 | E34: 43718 | F34: Marine | G34: Vinay | H34: Ahmedabad | I34: Marine | J34: Renewal | K34: 1072.5 | L34: 43354 | M34: Brokerage | N34: Inception | O34: 43852
A35: J | B35: '310304111710000871 | C35: Active | D35: 43186 | E35: 43550 | F35: Fire | G35: Vinay | H35: Ahmedabad | I35: Property / BI | J35: Renewal | K35: 4002.46 | L35: 43186 | M35: Brokerage | N35: Inception | O35: 43852
A36: J | B36: 3.1030411e+17 | C36: Active | D36: 43326 | E36: 43690 | F36: Fire | G36: Vinay | H36: Ahmedabad | I36: Property / BI | J36: Renewal | K36: 1374.25 | L36: 43326 | M36: Brokerage | N36: Inception | O36: 43852
A37: J | B37: 3.1030459e+18 | C37: Active | D37: 43186 | E37: 43550 | F37: Fire | G37: Vinay | H37: Ahmedabad | I37: Property / BI | J37: Cross Sell | K37: 566.25 | L37: 43186 | M37: Brokerage | N37: Inception | O37: 43852
A38: J | B38: '310304591810000063 | C38: Active | D38: 43326 | E38: 43690 | F38: Miscellaneous | G38: Vinay | H38: Ahmedabad | I38: Property / BI | J38: Renewal | K38: 445 | L38: 43326 | M38: Brokerage | N38: Inception | O38: 43852
A39: K | B39: '310300111910000401 | C39: Active | D39: 43709 | E39: 44074 | F39: Fire | G39: Vinay | H39: Ahmedabad | I39: Property / BI | J39: Renewal | K39: 13114.95 | L39: 43709 | M39: Brokerage | N39: Renewal | O39: 43852
A40: K | B40: 3.1030411e+17 | C40: Inactive | D40: 43344 | E40: 43708 | F40: Fire | G40: Vinay | H40: Ahmedabad | I40: Property / BI | J40: Renewal | K40: 2049.42 | L40: 43344 | M40: Brokerage | N40: Inception | O40: 43852
...

Sheet Cross sell
A1: income_class | B1: Cross Sell
A2: income_class | B2: Cross Sell
A4: Values
A5: Target | B5: 7290000
A6: Achivement | B6: 13041253
A7: Invoice | B7: 2853842

Sheet New
A1: income_class | B1: New
A2: income_class | B2: New
A4: Values
A5: Target | B5: 4100000
A6: Achivement | B6: 3531629.3
A7: Invoice | B7: 569815

Sheet Renewal
A1: income_class | B1: Renewal
A2: income_class | B2: Renewal
A4: Values
A5: Target | B5: 9520000
A6: Achivement | B6: 18507271
A7: Invoice | B7: 8244310

Sheet % Achivement
A2: Invoice
A3: Row Labels | B3: Sum of Amount | E3: Target
A4: Cross Sell | B4: 2853842 | E4: Sum of New Budget | F4: Sum of Cross sell bugdet | G4: Sum of Renewal Budget
A5: New | B5: 569815 | E5: 4100000 | F5: 7290000 | G5: 9520000
A6: Renewal | B6: 8244310
A7: Grand Total | B7: 11667967
E9: Cross Sell Placd Ach % | F9: Cross Sell Invoice Ach %
E10: =GETPIVOTDATA("[Measures].[Sum of Amount 2]",$A$18,"[Placed_achivement].[income_class]","[Placed_achivement].[income_class].&[Cross Sell]")/GETPIVOTDATA("Sum of Cross sell bugdet",$E$4) -> 1.7889236 | F10: =GETPIVOTDATA("Amount",$A$3,"income_class","Cross Sell")/GETPIVOTDATA("Sum of Cross sell bugdet",$E$4) -> 0.39147353
E13: New Placd Ach % | F13: New Invoice Ach %
E14: =GETPIVOTDATA("[Measures].[Sum of Amount 2]",$A$18,"[Placed_achivement].[income_class]","[Placed_achivement].[income_class].&[New]")/GETPIVOTDATA("Sum of New Budget",$E$4) -> 0.861373 | F14: =GETPIVOTDATA("Amount",$A$3,"income_class","New")/GETPIVOTDATA("Sum of New Budget",$E$4) -> 0.13897927
A17: Achivement | E17: Renewal Placd Ach % | F17: Renewal Invoice Ach %
A18: Row Labels | B18: Sum of Amount | E18: =GETPIVOTDATA("[Measures].[Sum of Amount 2]",$A$18,"[Placed_achivement].[income_class]","[Placed_achivement].[income_class].&[Renewal]")/GETPIVOTDATA("Sum of Renewal Budget",$E$4) -> 1.944041 | F18: =GETPIVOTDATA("Amount",$A$3,"income_class","Renewal")/GETPIVOTDATA("Sum of Renewal Budget",$E$4) -> 0.86599895
A19: Cross Sell | B19: 13041253
A20: New | B20: 3531629.3
A21: Renewal | B21: 18507271
A22: Grand Total | B22: 35080153

Sheet % achievement
A2: Formula | B2: Cross sell
A3: Achieved/Target | B3: Cross sell Plcd Achvmnt% | C3: ='[1]KPI 3.1'!C69/'[1]KPI 3.1'!C68 -> 0.58705063
A4: Invoice/Target | B4: Cross sell Inv Achvmnt% | C4: ='[1]KPI 3.1'!C70/'[1]KPI 3.1'!C68 -> 0.14210159
B6: New
A7: Achieved/Target | B7: New Plcd Achvmnt% | C7: ='[1]KPI 3.1'!C75/'[1]KPI 3.1'!C74 -> 0.16569861
A8: Invoice/Target | B8: New sell Inv Achvmnt% | C8: ='[1]KPI 3.1'!C76/'[1]KPI 3.1'!C74 -> 0.028963149
B10: Renewal
A11: Achieved/Target | B11: Renewal Plcd Achvmnt% | C11: ='[1]KPI 3.1'!C80/'[1]KPI 3.1'!C81 -> 0.66834911
A12: Invoice/Target | B12: Renewal Inv Achvmnt% | C12: ='[1]KPI 3.1'!C82/'[1]KPI 3.1'!C81 -> 0.44726631

Sheet KPI 1
A3: Count of invoice_number | B3: Column Labels
A4: Row Labels | B4: (blank) | C4: Cross Sell | D4: New | E4: Renewal | F4: Grand Total
A5: Neel Jain | D5: 1 | F5: 1
A6: Gautam Murkunde | B6: 1 | E6: 3 | F6: 4
A7: Nishant Sharma | C7: 10 | F7: 10
A8: Shobhit Agarwal | B8: 4 | C8: 2 | D8: 8 | F8: 14
A9: Vidit Shah | C9: 12 | E9: 15 | F9: 27
A10: Shloka Shelat | C10: 20 | D10: 7 | E10: 3 | F10: 30
A11: Ankita Shah | B11: 18 | E11: 18 | F11: 36
A12: Divya Dhingra | B12: 5 | C12: 19 | E12: 58 | F12: 82
A13: Grand Total | B13: 28 | C13: 63 | D13: 16 | E13: 97 | F13: 204

Sheet KPI 2
A3: Row Labels | B3: Count of Account Executive
A4: 2019 | B4: 3 | F4: Yearly Meeting Count
A5: 2020 | B5: 31 | F5: =A4 -> 2019 | G5: =A5 -> 2020
A6: Grand Total | B6: 34 | F6: =GETPIVOTDATA("[Measures].[Count of Account Executive]",$A$3,"[meeting_list_202001231041].[meeting_date (Year)]","[meeting_list_202001231041].[meeting_date (Year)].&[2019]") -> 3 | G6: =GETPIVOTDATA("[Measures].[Count of Account Executive]",$A$3,"[meeting_list_202001231041].[meeting_date (Year)]","[meeting_list_202001231041].[meeting_date (Year)].&[2020]") -> 31

Sheet KPI 4
A3: Row Labels | B3: Sum of revenue_amount
A4: Propose Solution | B4: 60000
A5: Negotiate | B5: 899000
A6: Qualify Opportunity | B6: 5919500
A7: Grand Total | B7: 6878500
B10: Qualify Opportunity | C10: 5919500
B11: Negotiate | C11: 899000
B12: Propose Solution | C12: 60000

Sheet KPI 5
A3: Row Labels | B3: Count of meeting_date
A4: Raju Kumar | B4: 2
A5: Mark | B5: 2
A6: Manish Sharma | B6: 3
A7: Juli | B7: 3
A8: Animesh Rawat | B8: 4
A9: Ketan Jain | B9: 4
A10: Shivani Sharma | B10: 4
A11: Vinay | B11: 5
A12: Abhinav Shivam | B12: 7
A13: Grand Total | B13: 34

Sheet KPI3
A3: Cross sell | B3: Refer sheet | H3: New | I3: Refer sheet | O3: Renewal | P3: Refer sheet
A4: Target | B4: Budget | C4: 20083111 | H4: Target | I4: Budget | J4: 19673793 | O4: Target | P4: Budget | Q4: 12319455
A5: Achievement | B5: Brokerage+Fees | C5: 11789803 | H5: Achievement | I5: Brokerage+Fees | J5: 3259920.1 | O5: Achievement | P5: Brokerage+Fees | Q5: 18432665
A6: Invoice | B6: invoice | C6: 2853842 | H6: Invoice | I6: invoice | J6: 569815 | O6: Invoice | P6: invoice | Q6: 8244310
A8: Cross sell | B8: Target | C8: Row Labels | D8: Sum of cross_sell_budget | H8: Cross sell | I8: Target | J8: Row Labels | K8: Sum of new_budget | O8: Cross sell | P8: Target | Q8: Row Labels | R8: Sum of renewal_budget
C9: Abhinav Shivam | D9: 129000 | J9: Abhinav Shivam | K9: 129902 | Q9: Abhinav Shivam | R9: 1289000
C10: Animesh Rawat | D10: 12365300 | J10: Animesh Rawat | K10: 1278023 | Q10: Animesh Rawat | R10: 12900
C11: Ankita Shah | D11: 0 | J11: Ankita Shah | K11: 0 | Q11: Ankita Shah | R11: 0
C12: Divya Dhingra | D12: 0 | J12: Divya Dhingra | K12: 0 | Q12: Divya Dhingra | R12: 0
C13: Gautam Murkunde | D13: 0 | J13: Gautam Murkunde | K13: 0 | Q13: Gautam Murkunde | R13: 0
C14: Gilbert | D14: 500000 | J14: Gilbert | K14: 1000000 | Q14: Gilbert | R14: 1010000
C15: Juli | D15: 3500000 | J15: Juli | K15: 1250000 | Q15: Juli | R15: 750000
C16: Ketan Jain | D16: 1250000 | J16: Ketan Jain | K16: 500000 | Q16: Ketan Jain | R16: 500000
C17: Kumar Jha | D17: 170034 | J17: Kumar Jha | K17: 1345000 | Q17: Kumar Jha | R17: 1298673
C18: Manish Sharma | D18: 750000 | J18: Manish Sharma | K18: 1350000 | Q18: Manish Sharma | R18: 750000
C19: Mark | D19: 128777 | J19: Mark | K19: 19888 | Q19: Mark | R19: 198882
C20: Neel Jain | D20: 0 | J20: Neel Jain | K20: 0 | Q20: Neel Jain | R20: 0
... C31: Target | D31: 20083111 | J31: Target | K31: 19673793 | Q31: Target | R31: 12319455
A33: Cross sell | B33: Achievement | C33: Row Labels | D33: Cross Sell(Brokerage) | E33: Row Labels | F33: Cross Sell(Fees) | H33: New | I33: Achievement | J33: New(Brokerage) | L33: New(Fees) | O33: New | P33: Achievement | Q33: Row Labels | R33: Renewal | S33: Row Labels | T33: Renewal
B34: (Brokerage+Fees) | C34: Abhinav Shivam | D34: 206294.29 | E34: Nishant Sharma | F34: 396480 | J34: Abhinav Shivam | K34: 567352.74 | L34: Abhinav Shivam | M34: 100000 | Q34: Abhinav Shivam | R34: 109812.12 | S34: Vinay | T34: 18051
C35: Animesh Rawat | D35: 543713.53 | J35: Animesh Rawat | K35: 55107.13 | Q35: Animesh Rawat | R35: 6412986.2
C36: Gilbert | J36: Juli | K36: 150230.05 | Q36: Gilbert | R36: 386738.25
C37: Juli | D37: 417 | J37: Ketan Jain | K37: 743804.31 | Q37: Juli | R37: 149485.39
C38: Ketan Jain | D38: 28087.5 | J38: Raju Kumar | K38: 100000 | Q38: Ketan Jain | R38: 369095.49
C39: Kumar Jha | J39: Vididt Saha | K39: 319390.82 | Q39: Kumar Jha | R39: 130049.5
C40: Manish Sharma | D40: 36357.09 | J40: Vinay | K40: 1224035 | Q40: Manish Sharma | R40: 29928.34
C41: Mark | D41: 63872.4 | J41: Grand Total | K41: 3159920.1 | L41: Grand Total | M41: 100000 | Q41: Mark | R41: 5001503.1
C42: Raju Kumar | D42: 821261.22 | Q42: Raju Kumar | R42: 452577.19
C43: Shivani Sharma | D43: 22047 | K43: Achievement | L43: =SUM(K41,M41) -> 3259920.1 | Q43: Shivani Sharma | R43: 888648.86
C44: Vididt Saha | D44: 1103800.2 | Q44: Vididt Saha | R44: 144957.51
C45: Vinay | D45: 8567472.7 | Q45: Vinay | R45: 4338831.7
C46: Grand Total | D46: 11393323 | E46: Grand Total | F46: 396480 | Q46: Grand Total | R46: 18414614 | S46: Grand Total | T46: 18051
D48: Achievement | E48: =SUM(D46,F46) -> 11789803 | Q48: Achievement | R48: =SUM(R46,T46) -> 18432665
A50: Cross sell | B50: Invoice | C50: Row Labels | D50: Cross Sell | H50: Renewal | I50: Invoice | J50: Row Labels | K50: New | O50: Renewal | P50: Invoice | Q50: Row Labels | R50: Renewal
C51: Abhinav Shivam | D51: 1012346 | J51: Neel Jain | K51: 84746 | Q51: Ankita Shah | R51: 1981422
C52: Animesh Rawat | D52: 443901 | J52: Shloka Shelat | K52: 224533 | Q52: Divya Dhingra | R52: 4351921
C53: Ankita Shah | J53: Shobhit Agarwal | K53: 260536 | Q53: Gautam Murkunde | R53: 305707
C54: Divya Dhingra | J54: Grand Total | K54: 569815 | Q54: Shloka Shelat | R54: 56098
C55: Gautam Murkunde | Q55: Vidit Shah | R55: 1549162
C56: Mark | D56: 90530 | J56: Invoice | K56: 569815 | Q56: Grand Total | R56: 8244310
...

Sheet KPI 6
H1: stage | I1: (Multiple Items)
A3: Row Labels | B3: Sum of revenue_amount | H3: Row Labels | I3: Sum of revenue_amount | O3: Total Opportunity
A4: Fire | B4: 500000 | H4: BE-Mega policy | I4: 300000 | O4: 49
A5: EL-Group Mediclaim | B5: 400000 | H5: CVP GMC | I5: 350000
A6: DB -Mega Policy | B6: 400000 | H6: DB -Mega Policy | I6: 400000
A7: CVP GMC | B7: 350000 | H7: DB -Terrorism Policy | I7: 300000
A8: Grand Total | B8: 1650000 | H8: DS- Employees GMC | I8: 300000
H9: EL-Group Mediclaim | I9: 400000
H10: FM-Group Mediclaim | I10: 300000
H11: Grand Total | I11: 2350000
M20: stage | N20: (Multiple Items)
K22: Total opportunity | M22: open opportunity
K23: 49 | M23: 44

Sheet KPI 7
A3: Row Labels | B3: Count of product_group
A4: Terrorism | B4: 1
A5: Miscellaneous | B5: 2
A6: Liability | B6: 5
A7: Engineering | B7: 6
A8: Marine | B8: 7
A9: Fire | B9: 13
A10: Employee Benefits | B10: 15
A11: Grand Total | B11: 49

Sheet Dashboard 
B18: Cross Sell Placd Ach % | D18: Cross Sell Invoice Ach % | F18: New Placd Ach % | H18: New Invoice Ach % | J18: Renewal Placd Ach % | L18: Renewal Invoice Ach %
B19: ='% Achivement'!E10 -> 1.7889236 | D19: ='% Achivement'!F10 -> 0.39147353 | F19: ='% Achivement'!E14 -> 0.861373 | H19: ='% Achivement'!F14 -> 0.13897927 | J19: ='% Achivement'!E18 -> 1.944041 | L19: ='% Achivement'!F18 -> 0.86599895
K21: Total Opprtunities | M21: Total Open Opportunities
K22: =GETPIVOTDATA("[Measures].[Count of opportunity_name]",'KPI 6'!$O$3) -> 49 | M22: =GETPIVOTDATA("opportunity_name",'KPI 6'!$M$22) -> 44
B23: 2019 | D23: 2020
B24: ='KPI 2'!F6 -> 3 | D24: ='KPI 2'!G6 -> 31
